Workbook

Sheet Dashboard 2023
A1: DASHBOARD - MAIN REASONS - 2023 | AP1: No
A2: Reason | B2: Total $ | C2: % | D2: CR | F2: Faturamento 2023 | G2: =252.626363992077 -> 252.62636
A3: Shipment delay | B3: 73636.32 | C3: 0.18023872 | D3: No
A4: Customer reschedule | B4: 52194.37 | C4: 0.12775552 | D4: Yes | F4: Premium Total | G4: =GETPIVOTDATA("Total $",$A$2)/1000000 -> 0.40854883
A5: Stock discrepancy | B5: 50584.37 | C5: 0.12381475 | D5: No | F5: % Premium Total/ fat | G5: =G4/G2 -> 0.0016172058
A6: Internal Strategy/ discount | B6: 44192.13 | C6: 0.10816854 | D6: No
A7: Project | B7: 44059.27 | C7: 0.10784334 | D7: Yes | F7: CR Non recoverable | G7: =(SUMIF($D$3:$D$20,$AP$1,$B$3:$B$20))/1000000 -> 0.26143235
A8: Internal problem - Manufacturing/ Ordering/ Purchasing/ IT | B8: 41301.74 | C8: 0.10109377 | D8: No | F8: % CR Non recoverable/ fat | G8: =G7/G2 -> 0.0010348577
A9: Supplier delay | B9: 33215.36 | C9: 0.081300833 | D9: Yes
A10: Lead time discrepancy between supplier/ customer | B10: 21926.49 | C10: 0.053669203 | D10: No
A11: Freight to be recovery at POV | B11: 17647.48 | C11: 0.043195522 | D11: Yes
A12: Força maior | B12: 6811.93 | C12: 0.016673478 | D12: No
A13: Cargo lost | B13: 6265.32 | C13: 0.015335548 | D13: No
A14: Lack of packaging | B14: 5926.78 | C14: 0.014506907 | D14: No
A15: P&A | B15: 4672.48 | C15: 0.011436772 | D15: No
A16: Stoled cargo | B16: 2692.61 | C16: 0.0065906687 | D16: No
A17: BOM error | B17: 2549.16 | C17: 0.0062395479 | D17: No
A18: Quality problem | B18: 873.02 | C18: 0.0021368804 | D18: No
A19: Total Geral | B19: 408548.83 | C19: 1

Sheet Details 2023
I1: =SUBTOTAL(9,I3:I920) -> 408548.83
A2: MÊS REPORTE | B2: MOTIVO | C2: PREMIUM_ID | D2: PBU_NAME | E2: CUSTOMER | F2: SHIPMENT_DATE | G2: PLANT_NAME | H2: SHIPMENT_TYPE | I2: ACTUAL_COST_IN_USD | J2: ESTIMATED_COST_IN_USD | K2: Percentual | L2: PREMIUM_REASON_CODE | M2: ORIG_PREMIUM_REASON_CODE | N2: SHIP_TO_NAME | O2: SHIP_FROM_NAME | P2: PROBLEM_DESCRIPTION | Q2: CARRIER_NAME | R2: PTA_NUMBER | S2: PART_NUMBERS_TEXT | T2: QUANTITY(In Pieces) | U2: WEIGHT | V2: COST_RECOVERY | W2: COMMODITY_TYPE | X2: SUBMITTED_BY_NAME | Y2: SUBMIT_DATE | Z2: EDIT_DATE | AA2: REGION_NAME | AB2: RECOVERY_STATUS | AC2: RECOVERED_COST_IN_USD | AD2: RECOVERED_DATE | AE2: ORIG_FREIGHT_COST_USD | AF2: LAUNCH_PERIOD | AG2: PLANT_CODE | AH2: SOURCE_SYSTEM | AI2: RECOVERED_LC | AJ2: ACTUAL_SHIP_COST_LC | AK2: COST_RECOVERY_REQUIRED | AL2: COST_RECOVERY_TRACKING | AM2: ESTIM_SHIP_COST_LC | AN2: INVOICE_CURRENCY | AO2: SHIP_FROM_ADDRESS | AP2: SHIP_FROM_CITY | AQ2: SHIP_FROM_CODE | AR2: SHIP_FROM_COUNTRY | AS2: SHIP_FROM_REGION | AT2: SHIP_FROM_STATE | AU2: SHIP_FROM_ZIP | AV2: SHIP_TO_ADDRESS | AW2: SHIP_TO_CITY | AX2: SHIP_TO_CODE | AY2: SHIP_TO_COUNTRY | AZ2: SHIP_TO_REGION | BA2: SHIP_TO_STATE | BB2: SHIP_TO_ZIP | BC2: SEGMENT | BD2: APPROVAL_STATUS | BE2: APPROVED_BY_NAME | BF2: APPROVED_DATE | BG2: TMS_LOAD_ID | BH2: ACTUAL_CARRIER | BI2: ACTUAL_CARRIER_TRACKING_NUMBER | BJ2: PREMIUM_REASON_CODE_ACTUAL | BK2: DRIVER | BL2: ACTUAL_DRIVER | BM2: ESTIMATED_COST_SOURCE | BN2: ACTUAL_COST_SOURCE | BO2: ACTUAL_CUSTOMER | BP2: ACTUAL_SUPPLIER | BQ2: TOTAL_APPROVAL_TIME | BR2: APPROVED_LEVEL_AMOUNT(USD) | BS2: APPROVER_COMMENTS | BT2: TOTAL_COST | BU2: TOTAL_COST_LESS_RECOVERIES | BV2: NO_OF_CONTAINER | BW2: DIMENSION_OF_BOX(HxWxL) | BX2: UOM | BY2: COUNTRY | BZ2: FAMILY_NAME/PROGRAM | CA2: ESTIMATED_NAME_OF_INVOICE_CURRENCY | CB2: TOP_100_SUPPLIER | CC2: NAME_OF_RECOVERED_CURRENCY | CD2: UNIT_WEIGHTS | CE2: ADDITIONAL_COMMENTARY | CF2: ESTIMATE_INVOICE_EXCHANGE_RATE | CG2: ACTUAL_INVOICE_EXCHANGE_RATE | CH2: ACTUAL_RECOVERED_INVOICE_EXCHANGE_RATE | CI2: NORMAL_SHIPMENT_COST_IN_INVOICE_CURRENCY | CJ2: NORMAL_SHIPMENT_COST_(USD) | CK2: NAME_OF_NORMAL_SHIPMENT_INVOICE_CURRENCY | CL2: NORMAL_INVOICE_EXCHANGE_RATE | CM2: PROBLEM_REASON_CODE_ACTUAL | CN2: CANCELLATION_REMARK | CO2: SHIP_FROM_DUNS | CP2: SHIP_TO_DUNS | CQ2: ACTUAL_SUPPLIER_DUNS
A3: 44927 | B3: Internal problem - Manufacturing/ Ordering/ Purchasing/ IT | C3: 39680 | D3: Manufacturing Delay | E3: GM | F3: 44929 | G3: Ouros | H3: Outbound Premium | I3: 198.23 | J3: 197.23 | K3: =I3/$I$1 -> 0.00048520516 | L3: M1L-Manufacturing low efficiency | M3: Normal | N3: GENERAL MOTORS (72664)-700535 | O3: APTIV MANUFATURA E SERVICOS DE-104120 | P3: Manufacturing Delay | Q3: TRANSPORTADORA PITUTA | R3: PTA-00085578 | S3: 35548247; | T3: ; | U3: ; | V3: Aptiv | W3: Premium - Productive | X3: adriane.barbosa.silva@aptiv.com | Y3: 44929.107 | Z3: 44931.092 | AA3: SA | AB3: Closed Not Recovered | AC3: 0 | AE3: 19823 | AG3: 10023 | AH3: Q11 | AJ3: 104943 | AK3: Non-Recoverable | AM3: 104415 | AN3: BRL | AO3: AVENIDA AVELINO RIBEIRO, 900 | AP3: PARAISOPOLIS | AQ3: 104120 | AR3: BR | AS3: SA | AT3: MG | AU3: 37660-000 | AV3: CISCO 72664 | AW3: SAO JOSE DOS CAMPOS | AX3: 700535 | AY3: BR | AZ3: SA | BA3: SP | BB3: 12224-300 | BC3: SPS | BD3: Approved | BE3: Rebello, Andre | BF3: 44929.287 | BG3: 0 | BH3: TRANSPORTADORA PITUTA | BI3: PAR-000204432 | BK3: Aptiv | BM3: Invoice | BN3: Invoice | BQ3: 0 Days 4 Hr 20 Min | BR3: 500 | BS3: Approved - ;; Approved - ; | BT3: 19823 | BU3: 19823 | BV3: ; | BW3: ; | BX3: ; | BY3: BR | CA3: BRL | CF3: 18888952 | CG3: 18888952 | CJ3: 0
A4: 44927 | B4: Shipment delay | C4: 39789 | D4: Transportation Problem - Atraso ETA | E4: JOHN DEERE | F4: 44929 | G4: Paraisopolis | H4: Inbound Premium | I4: 56.43 | J4: 90 | K4: =I4/$I$1 -> 0.00013812302 | L4: T1-Transportation | M4: Normal | N4: APTIV MANUFATURA E SERVICOS DE-104120 | O4: APTIV WARREN (FR09)-702235 | P4: CONGESTIONAMENTO DOS PORTOS | Q4: DHL Express SA | R4: PTA-00085583 | S4: 12129615; | T4: ; | U4: ; | V4: Aptiv | W4: Premium - Productive | X4: Moraes.Arnaldo@aptiv.com | Y4: 44929.295 | Z4: 44936.275 | AA4: SA | AB4: Closed Not Recovered | AC4: 0 | AE4: 5643 | AG4: 10012 | AH4: Q11 | AJ4: 5643 | AK4: Non-Recoverable | AM4: 90 | AN4: USD | AO4: 1265 N RIVER RD NE | AP4: WARREN | AQ4: 702235 | AR4: US | AS4: NA | AT4: OH | AU4: 44483 | AV4: AVENIDA AVELINO RIBEIRO, 900 | AW4: PARAISOPOLIS | AX4: 104120 | AY4: BR | AZ4: SA | BA4: MG | BB4: 37660-000 | BC4: SPS | BD4: Approved | BE4: Rebello, Andre | BF4: 44929.324 | BG4: 0 | BH4: DHL Express SA | BI4: 8449388835 | BK4: Transportation | BM4: Invoice | BN4: Invoice | BQ4: 0 Days 0 Hr 42 Min | BR4: 500 | BS4: Approved - ;; Approved - ; | BT4: 5643 | BU4: 5643 | BV4: ; | BW4: ; | BX4: ; | BY4: BR | CA4: USD | CE4: POR ERRO DO FORNECEDOR FOI EMBARCADO EM DIFERENTE TRACKING SEM PTA | CF4: 1 | CG4: 1 | CJ4: 0
A5: 44927 | B5: Shipment delay | C5: 39792 | D5: Transportation Problem - Atraso ETA | E5: JOHN DEERE | F5: 44929 | G5: Paraisopolis | H5: Inbound Premium | I5: 84.97 | J5: 80 | K5: =I5/$I$1 -> 0.00020798004 | L5: T1-Transportation | M5: Normal | N5: APTIV MANUFATURA E SERVICOS DE-104120 | O5: APTIV WARREN (FR09)-702235 | P5: CONGESTIONAMENTO DOS PORTOS | Q5: DHL Express SA | R5: PTA-00085582 | S5: 02973407; | T5: ; | U5: ; | V5: Aptiv | W5: Premium - Productive | X5: Moraes.Arnaldo@aptiv.com | Y5: 44929.296 | Z5: 44936.272 | AA5: SA | AB5: Closed Not Recovered | AC5: 0 | AE5: 8497 | AG5: 10012 | AH5: Q11 | AJ5: 8497 | AK5: Non-Recoverable | AM5: 80 | AN5: USD | AO5: 1265 N RIVER RD NE | AP5: WARREN | AQ5: 702235 | AR5: US | AS5: NA | AT5: OH | AU5: 44483 | AV5: AVENIDA AVELINO RIBEIRO, 900 | AW5: PARAISOPOLIS | AX5: 104120 | AY5: BR | AZ5: SA | BA5: MG | BB5: 37660-000 | BC5: SPS | BD5: Approved | BE5: Rebello, Andre | BF5: 44929.324 | BG5: 0 | BH5: DHL Express SA | BI5: 8449406512 | BK5: Transportation | BM5: Invoice | BN5: Invoice | BQ5: 0 Days 0 Hr 40 Min | BR5: 500 | BS5: Approved - ;; Approved - ; | BT5: 8497 | BU5: 8497 | BV5: ; | BW5: ; | BX5: ; | BY5: BR | CA5: USD | CE5: POR ERRO DO FORNECEDOR FOI EMBARCADO EM DIFERENTE TRACKING SEM PTA | CF5: 1 | CG5: 1 | CJ5: 0
A6: 44927 | B6: Shipment delay | C6: 40049 | D6: Transportation Problem - Atraso ETA | E6: TOYOTA | F6: 44931 | G6: Paraisopolis | H6: Inbound Premium | I6: 119.41 | J6: 100 | K6: =I6/$I$1 -> 0.0002922784 | L6: T1-Transportation | M6: Normal | N6: APTIV MANUFATURA E SERVICOS DE-104120 | O6: APTIV PLANT FR47-725460 | P6: Congestionamento dos portos devido o feriado de Thanksgiving nos EUA | Q6: DHL Express SA | R6: PTA-00085850 | S6: 15317587; | T6: ; | U6: ; | V6: Aptiv | W6: Premium - Productive | X6: Moraes.Arnaldo@aptiv.com | Y6: 44930.225 | Z6: 44937.244 | AA6: SA | AB6: Closed Not Recovered | AC6: 0 | AE6: 11941 | AG6: 10012 | AH6: Q11 | AJ6: 11941 | AK6: Non-Recoverable | AM6: 100 | AN6: USD | AO6: 3400 AERO PARK DR | AP6: VIENNA | AQ6: 725460 | AR6: US | AS6: NA | AT6: OH | AU6: 44473-8704 | AV6: AVENIDA AVELINO RIBEIRO, 900 | AW6: PARAISOPOLIS | AX6: 104120 | AY6: BR | AZ6: SA | BA6: MG | BB6: 37660-000 | BC6: SPS | BD6: Approved | BE6: Rebello, Andre | BF6: 44930.333 | BG6: 0 | BH6: DHL Express SA | BI6: 6911280961 | BK6: Transportation | BM6: Personal Estimate | BN6: Invoice | BQ6: 0 Days 2 Hr 36 Min | BR6: 500 | BS6: Approved - ;; Approved - ; | BT6: 11941 | BU6: 11941 | BV6: ; | BW6: ; | BX6: ; | BY6: BR | CA6: USD | CE6: 13697415 | CF6: 1 | CG6: 1 | CJ6: 0
A7: 44927 | B7: Shipment delay | C7: 40090 | D7: Transportation Problem - Atraso ETA | E7: TOYOTA | F7: 44932 | G7: Paraisopolis | H7: Inbound Premium | I7: 162.56 | J7: 120 | K7: =I7/$I$1 -> 0.00039789613 | L7: T1-Transportation | M7: Normal | N7: APTIV MANUFATURA E SERVICOS DE-104120 | O7: APTIV LAREDO (FW80)-734188 | P7: ongestionamento dos portos devido feriado de Thanksgiving nos EUA. | Q7: DHL Express SA | R7: PTA-00085945 | S7: 13533399; | T7: ; | U7: ; | V7: Aptiv | W7: Premium - Productive | X7: Moraes.Arnaldo@aptiv.com | Y7: 44930.334 | Z7: 44937.26 | AA7: SA | AB7: Closed Not Recovered | AC7: 0 | AE7: 16256 | AG7: 10012 | AH7: Q11 | AJ7: 16256 | AK7: Recoverable | AM7: 120 | AN7: USD | AO7: 301 VALLECILLO ROAD | AP7: LAREDO | AQ7: 734188 | AR7: US | AS7: NA | AT7: TX | AU7: 78045-7847 | AV7: AVENIDA AVELINO RIBEIRO, 900 | AW7: PARAISOPOLIS | AX7: 104120 | AY7: BR | AZ7: SA | BA7: MG | BB7: 37660-000 | BC7: SPS | BD7: Approved | BE7: Rebello, Andre | BF7: 44931.463 | BG7: 0 | BH7: DHL Express SA | BI7: 2469905561 | BK7: Transportation | BM7: Invoice | BN7: Invoice | BQ7: 0 Days 15 Hr 6 Min | BR7: 500 | BS7: Approved - ;; Approved - ; | BT7: 16256 | BU7: 16256 | BV7: ; | BW7: ; | BX7: ; | BY7: BR | CA7: USD | CE7: 15305104-13697408 | CF7: 1 | CG7: 1 | CJ7: 0
A8: 44927 | B8: Supplier delay | C8: 40459 | D8: Supplier Delay - MTA | E8: JOHN DEERE | F8: 44932 | G8: Paraisopolis | H8: Inbound Premium | I8: 549 | J8: 640.97 | K8: =I8/$I$1 -> 0.0013437806 | L8: B3-Behind Schedule-External Supplier | M8: Cost Recovery Pending | N8: Paraisopolis-10012 | O8: MTA S P A-107597 | P8: Erro comercial do lado da MTA (COST RECOVERY SIM) | Q8: DHL Express SA | R8: PTA-00086142 | S8: 13673199 - 13881229; | T8: ; | U8: ; | V8: Supplier | W8: Premium - Productive | X8: william.de.siqueira@aptiv.com | Y8: 44932.462 | Z8: 44942.22 | AA8: SA | AB8: Open | AC8: 0 | AE8: 549 | AF8: 44938 | AG8: 10012 | AH8: Q11 | AJ8: 549 | AK8: Recoverable | AM8: 64097 | AN8: USD | AO8: VIALE DELLINDUSTRIA 12 | AP8: CODOGNO | AQ8: 107597 | AR8: IT | AS8: EMEA | AT8: LO | AU8: 26845 | AV8: Av. Avelino Ribeiro, 900 | AW8: Paraisopolis | AX8: 10012 | AY8: BR | AZ8: SA | BA8: Mina | BB8: 37660-000 | BC8: SPS | BD8: Approved | BE8: Naus, Angelica | BF8: 44932.072 | BG8: 0 | BI8: 4553768041 | BK8: Supplier | BM8: Invoice | BN8: Invoice | BP8: MTA SPA-8019235 | BQ8: 0 Days 2 Hr 37 Min | BR8: 800 | BS8: Approved - ;; Approved - ;; Approved - ; | BT8: 549 | BU8: 549 | BV8: ; | BW8: ; | BX8: ; | BY8: BR | CA8: USD | CB8: HONGFA TECHNOLOGY CO, LTD ULT DUNS 545268450 | CF8: 1 | CG8: 1 | CJ8: 0
A9: 44927 | B9: Shipment delay | C9: 40504 | D9: Transportation Problem - Atraso ETA | E9: JOHN DEERE | F9: 44935 | G9: Paraisopolis | H9: Inbound Premium | I9: 347.18 | J9: 301.58 | K9: =I9/$I$1 -> 0.00084978826 | L9: T1-Transportation | M9: Normal | N9: APTIV MANUFATURA E SERVICOS DE-104120 | O9: APTIV CENTEC II (FW97)-726918 | P9: Congestionamento dos portos devido feriado de thanksgiving nos EUA | Q9: DHL Express SA | R9: PTA-00086275 | S9: 10763696; | T9: ; | U9: ; | V9: Aptiv | W9: Premium - Productive | X9: Moraes.Arnaldo@aptiv.com | Y9: 44932.174 | Z9: 44939.287 | AA9: SA | AB9: Closed Not Recovered | AC9: 0 | AE9: 34718 | AG9: 10012 | AH9: Q11 | AJ9: 34718 | AK9: Non-Recoverable | AM9: 30158 | AN9: USD | AO9: BLVD ISIDRO LOPEZ ZERTUCHE 4890 | AP9: SALTILLO | AQ9: 726918 | AR9: MX | AS9: NA | AT9: COA | AU9: 25230 | AV9: AVENIDA AVELINO RIBEIRO, 900 | AW9: PARAISOPOLIS | AX9: 104120 | AY9: BR | AZ9: SA | BA9: MG | BB9: 37660-000 | BC9: SPS | BD9: Approved | BE9: Rebello, Andre | BF9: 44932.495 | BG9: 0 | BH9: DHL Express SA | BI9: 1017181196 | BK9: Transportation | BM9: Invoice | BN9: Invoice | BQ9: 0 Days 7 Hr 42 Min | BR9: 500 | BS9: Approved - ;; Approved - ; | BT9: 34718 | BU9: 34718 | BV9: ; | BW9: ; | BX9: ; | BY9: BR | CA9: USD | CE9: 15544892-15544324-33386302 | CF9: 1 | CG9: 1 | CJ9: 0
A10: 44927 | B10: Stock discrepancy | C10: 40525 | D10: Stock Discrepancy | E10: GM | F10: 44932 | G10: Pinhal | H10: Inbound Premium | I10: 2500 | J10: 2500 | K10: =I10/$I$1 -> 0.0061192196 | L10: S1I-Inventory loss/adjustments | M10: Normal | N10: APTIV MANUFATURA E SERVICOS DE-104991 | O10: APTIV HONDURAS HN11-765569 | P10: We had some problems in the transportation of Aptiv Hondura's materials that results in iventory loss. | Q10: DSV UTI Air & Sea Agenciamento de Transportes | S10: 47315376; | T10: ; | U10: ; | V10: Aptiv | W10: Premium - Productive | X10: rodrigo.perez@aptiv.com | Y10: 44957.111 | Z10: 44957.11 | AA10: SA | AB10: Closed Not Recovered | AC10: 0 | AE10: 0 | AF10: 44935 | AG10: 10010 | AH10: Q18 | AK10: Non-Recoverable | AM10: 2500 | AO10: KM 23/24 CARRETERA A OCCIDENTE ZOLI | AP10: QUIMISTAN | AQ10: 765569 | AR10: HN | AS10: NA | AT10: SB | AU10: 22101 | AV10: RODOVIA SP 342 KM 196 | AW10: ESPIRITO SANTO DO PINHAL | AX10: 104991 | AY10: BR | AZ10: SA | BA10: SP | BB10: 13990-000 | BC10: SPS | BD10: Pending | BG10: 0 | BH10: DSV UTI Air & Sea Agenciamento de Transportes | BK10: Aptiv | BM10: Personal Estimate | BN10: Personal Estimate | BR10: 0 | BS10: Approved - ;; Approved - ;; Approved - ;; Approved - ok ;; Pending - | BT10: 2500 | BU10: 2500 | BV10: ; | BW10: ; | BX10: ; | BY10: BR | CA10: USD | CF10: 1 | CJ10: 0
A11: 44927 | B11: BOM error | C11: 40542 | D11: BOM Error | E11: OTHER | F11: 44932 | G11: Paraisopolis | H11: Inbound Premium | I11: 148.89 | J11: 134.16 | K11: =I11/$I$1 -> 0.00036443624 | L11: E1B-BOM Errors | M11: Normal | N11: APTIV MANUFATURA E SERVICOS DE-106499 | O11: TECNOPRINT AUTOMACAO INDUSTRIAL LTDA-8125875 | P11: BOM Error | Q11: TRANSPORTADORA PITUTA | R11: PTA-00086274 | S11: 15368456; | T11: ; | U11: ; | V11: Aptiv | W11: Premium - Productive | X11: adriane.barbosa.silva@aptiv.com | Y11: 44932.249 | Z11: 44942.299 | AA11: SA | AB11: Closed Not Recovered | AC11: 0 | AE11: 14889 | AG11: 10012 | AH11: Q11 | AJ11: 77684 | AK11: Non-Recoverable | AM11: 700 | AN11: BRL | AO11: RUA SALVADOR DE SA 34/44 | AP11: SANTO ANDRE | AQ11: 8125875 | AR11: BR | AS11: SA | AT11: _ | AU11: 09210-490 | AV11: 900 AVENUE AVELINO RIBEIRO | AW11: PARAISOPOLIS | AX11: 106499 | AY11: BR | AZ11: SA | BA11: MG | BB11: 37660-000 | BC11: SPS | BD11: Approved | BE11: Rebello, Andre | BF11: 44932.495 | BG11: 0 | BI11: GRU-000896251 | BK11: Aptiv | BM11: Invoice | BN11: Invoice | BQ11: 0 Days 5 Hr 54 Min | BR11: 500 | BS11: Approved - ;; Approved - ; | BT11: 14889 | BU11: 14889 | BV11: ; | BW11: ; | BX11: ; | BY11: BR | CA11: BRL | CF11: 19165533 | CG11: 19165533 | CJ11: 0
A12: 44927 | B12: Shipment delay | C12: 40784 | D12: Transportation Problem - Atraso ETA | E12: GM | F12: 44936 | G12: Pinhal | H12: Inbound Premium | I12: 819.62 | J12: 150 | K12: =I12/$I$1 -> 0.0020061739 | L12: T1-Transportation | M12: Normal | N12: APTIV MANUFATURA E SERVICOS DE-104991 | O12: J.S.T. CORPORATION-1003317 | P12: Aéreo necessário devido ao atraso de ETA, Invoice 739741. | Q12: DHL Express SA | R12: PTA-00086456 | S12: 13646861; | T12: ; | U12: ; | V12: Aptiv | W12: Premium - Productive | X12: rodrigo.perez@aptiv.com | Y12: 44935.522 | Z12: 44957.514 | AA12: SA | AB12: Closed Not Recovered | AC12: 0 | AE12: 81962 | AF12: 44936 | AG12: 10010 | AH12: Q18 | AJ12: 81962 | AK12: Non-Recoverable | AM12: 150 | AN12: USD | AO12: 1957 S LAKESIDE DR | AP12: WAUKEGAN | AQ12: 1003317 | AR12: US | AS12: NA | AT12: IL | AU12: 60085-8331 | AV12: RODOVIA SP 342 KM 196 | AW12: ESPIRITO SANTO DO PINHAL | AX12: 104991 | AY12: BR | AZ12: SA | BA12: SP | BB12: 13990-000 | BC12: SPS | BD12: Approved | BE12: Edilson, Geraldo | BF12: 44935.28 | BG12: 0 | BH12: DHL Express SA | BI12: 8945077665 | BK12: Transportation | BM12: Personal Estimate | BN12: Personal Estimate | BQ12: 0 Days 6 Hr 11 Min | BR12: 500 | BS12: Approved - ;; Approved - ; | BT12: 81962 | BU12: 81962 | BV12: ; | BW12: ; | BX12: ; | BY12: BR | CA12: USD | CF12: 1 | CG12: 1 | CJ12: 0 | CO12: 690666524
A13: 44927 | B13: Stock discrepancy | C13: 40790 | D13: Stock Discrepancy | E13: JOHN DEERE | F13: 44935 | G13: Paraisopolis | H13: Inbound Premium | I13: 517.47 | J13: 517.47 | K13: =I13/$I$1 -> 0.001266605 | L13: S1I-Inventory loss/adjustments | M13: Normal | N13: APTIV MANUFATURA E SERVICOS DE-106499 | O13: Acome Irati-Dummy | P13: Stock Discrepancy | Q13: TRANSPORTADORA PITUTA | R13: PTA-00087990 | S13: 15368456; | T13: ; | U13: ; | V13: Aptiv | W13: Premium - Productive | X13: adriane.barbosa.silva@aptiv.com | Y13: 44942.065 | Z13: 44946.235 | AA13: SA | AB13: Closed Not Recovered | AC13: 0 | AE13: 0 | AG13: 10012 | AH13: Q11 | AJ13: 492499 | AK13: Non-Recoverable | AM13: 2700 | AN13: BRL | AO13: Irati | AP13: Irati | AQ13: Dummy | AR13: BR | AS13: SA | AT13: Parana | AU13: 0000 | AV13: 900 AVENUE AVELINO RIBEIRO | AW13: PARAISOPOLIS | AX13: 106499 | AY13: BR | AZ13: SA | BA13: MG | BB13: 37660-000 | BC13: SPS | BD13: Approved | BE13: Naus, Angelica | BF13: 44942.245 | BG13: 0 | BH13: TRANSPORTADORA PITUTA | BI13: COL-000009739 | BK13: Aptiv | BM13: Invoice | BN13: Invoice | BQ13: 0 Days 4 Hr 19 Min | BR13: 800 | BS13: Approved - ;; Approved - ;; Approved - ;; Approved - ; | BT13: 51747 | BU13: 51747 | BV13: ; | BW13: ; | BX13: ; | BY13: BR | CA13: BRL | CF13: 19165533 | CG13: 19165533 | CJ13: 0
A14: 44927 | B14: Project | C14: 40861 | D14: Projeto | E14: GM | F14: 44935 | G14: Paraisopolis | H14: Inbound Premium | I14: 77 | J14: 77 | K14: =I14/$I$1 -> 0.00018847196 | L14: E1P-Prototypes/Samples | M14: Cost Recovery | N14: Paraisopolis-10012 | O14: SERENDIPITY ELECTRONICS-749804 | P14: Parts for sales from protoypes pieces. Freigth included in the piece price. | Q14: DHL Express SA | R14: PTA-00086459 | S14: 13894085; | T14: ; | U14: ; | V14: Aptiv | W14: Premium - Productive | X14: rayzza.peres@aptiv.com | Y14: 44935.278 | Z14: 44935.277 | AA14: SA | AB14: Closed Recovered | AC14: 0 | AE14: 77 | AG14: 10012 | AH14: Q11 | AJ14: 77 | AK14: Recoverable | AM14: 77 | AN14: USD | AO14: 152 E MAIN ST | AP14: HUNTINGTON | AQ14: 749804 | AR14: US | AS14: NA | AT14: NY | AU14: 11743-2958 | AV14: Av. Avelino Ribeiro, 900 | AW14: Paraisopolis | AX14: 10012 | AY14: BR | AZ14: SA | BA14: Mina | BB14: 37660-000 | BC14: SPS | BD14: Approved | BE14: Edilson, Geraldo | BF14: 44935.286 | BG14: 0 | BK14: Aptiv | BM14: Invoice | BN14: Invoice | BQ14: 0 Days 0 Hr 10 Min | BR14: 500 | BS14: Approved - ;; Approved - ; | BT14: 77 | BU14: 77 | BV14: ; | BW14: ; | BX14: ; | BY14: BR | BZ14: PL8 | CA14: USD | CE14: DPP67515 | CF14: 1 | CG14: 1 | CJ14: 0
A15: 44927 | B15: Supplier delay | C15: 40905 | D15: Supplier Delay - Serendipity | E15: JOHN DEERE | F15: 44936 | G15: Paraisopolis | H15: Inbound Premium | I15: 40.13 | J15: 40.13 | K15: =I15/$I$1 -> 9.8225713e-05 | L15: B3-Behind Schedule-External Supplier | M15: Cost Recovery Pending | N15: Paraisopolis-10012 | O15: SERENDIPITY ELECTRONICS-749804 | P15: Atraso do fornecedor - Cost recovery sim | Q15: DHL Express SA | R15: PTA-00086461 | S15: 13934466; | T15: ; | U15: ; | V15: Supplier | W15: Premium - Productive | X15: william.de.siqueira@aptiv.com | Y15: 44935.266 | Z15: 44942.221 | AA15: SA | AB15: Open | AC15: 0 | AE15: 4013 | AF15: 44942 | AG15: 10012 | AH15: Q11 | AJ15: 4013 | AK15: Recoverable | AM15: 4013 | AN15: USD | AO15: 152 E MAIN ST | AP15: HUNTINGTON | AQ15: 749804 | AR15: US | AS15: NA | AT15: NY | AU15: 11743-2958 | AV15: Av. Avelino Ribeiro, 900 | AW15: Paraisopolis | AX15: 10012 | AY15: BR | AZ15: SA | BA15: Mina | BB15: 37660-000 | BC15: SPS | BD15: Approved | BE15: Edilson, Geraldo | BF15: 44935.286 | BG15: 0 | BI15: 2469837436 | BK15: Supplier | BM15: Invoice | BN15: Invoice | BP15: SERENDIPITY ELECTRONICS, INC.-8115180 | BQ15: 0 Days 0 Hr 28 Min | BR15: 500 | BS15: Approved - ;; Approved - ; | BT15: 4013 | BU15: 4013 | BV15: ; | BW15: ; | BX15: ; | BY15: BR | CA15: USD | CB15: MTA SPA ULT DUNS 428456263 | CF15: 1 | CG15: 1 | CJ15: 0
A16: 44927 | B16: Project | C16: 41113 | D16: Engineering Changes | E16: DAIMLER | F16: 44936 | G16: Paraisopolis | H16: Inbound Premium | I16: 567.67 | J16: 567.67 | K16: =I16/$I$1 -> 0.001389479 | L16: E1D-Aptiv Design/Engineering changes | M16: Normal | N16: APTIV MANUFATURA E SERVICOS DE-104120 | O16: FRAENKISCHE INDUSTRIAL PIPES GMBH &-1049617 | P16: Critical material to meet engineering modification, as per customer request due to quality problem. | Q16: DHL Express SA | R16: PTA-00086682 | S16: M3794521; | T16: 2000 metros; | U16: 89.80; | V16: Aptiv | W16: Premium - Productive | X16: marcia.p.torres@aptiv.com | Y16: 44936.452 | Z16: 44960.227 | AA16: SA | AB16: Closed Not Recovered | AC16: 0 | AE16: 0 | AF16: 44936 | AG16: 10012 | AH16: Q11 | AJ16: 833 | AK16: Non-Recoverable | AM16: 83309 | AO16: HELLINGER STR. 1 | AP16: KOENIGSBERG I.BAY. | AQ16: 1049617 | AR16: DE | AS16: EMEA | AT16: BY | AU16: 97486 | AV16: AVENIDA AVELINO RIBEIRO, 900 | AW16: PARAISOPOLIS | AX16: 104120 | AY16: BR | AZ16: SA | BA16: MG | BB16: 37660-000 | BC16: SPS | BD16: Approved | BE16: Naus, Angelica | BF16: 44936.232 | BG16: 0 | BI16: 6905119104 | BK16: Aptiv | BM16: Invoice | BN16: Invoice | BQ16: 0 Days 6 Hr 42 Min | BR16: 800 | BS16: Approved - ;; Approved - ;; Approved - ok ; | BT16: 56767 | BU16: 56767 | BV16: ; | BW16: 1200x800x950; | BX16: ; | BY16: BR | BZ16: MOTOR | CA16: AUD | CD16: Kg | CE16: Critical material to meet engineering modification, as per customer request due to quality problem. MBB | CF16: 6814 | CJ16: 0 | CO16: 329846877
A17: 44927 | B17: Stock discrepancy | C17: 41136 | D17: Stock Discrepancy | E17: FIAT | F17: 44937 | G17: Paraisopolis | H17: Inbound Premium | I17: 463.27 | J17: 670 | K17: =I17/$I$1 -> 0.0011339403 | L17: S1I-Inventory loss/adjustments | M17: Normal | N17: Paraisopolis-10012 | O17: MTA SPA-1014076 | P17: Reajuste de estoque | Q17: DHL Express SA | R17: PTA-00086681 | S17: 15369145 - 13864152 - 10820257; | T17: ; | U17: ; | V17: Aptiv | W17: Premium - Productive | X17: william.de.siqueira@aptiv.com | Y17: 44936.082 | Z17: 44942.229 | AA17: SA | AB17: Closed Not Recovered | AC17: 0 | AE17: 46327 | AF17: 44942 | AG17: 10012 | AH17: Q11 | AJ17: 46327 | AK17: Non-Recoverable | AM17: 670 | AN17: USD | AO17: VIALE DELLINDUSTRIA 12 | AP17: CODOGNO | AQ17: 1014076 | AR17: IT | AS17: EMEA | AT17: LO | AU17: 26845 | AV17: Av. Avelino Ribeiro, 900 | AW17: Paraisopolis | AX17: 10012 | AY17: BR | AZ17: SA | BA17: Mina | BB17: 37660-000 | BC17: SPS | BD17: Approved | BE17: Naus, Angelica | BF17: 44936.231 | BG17: 0 | BI17: 5372890401 | BK17: Aptiv | BM17: Invoice | BN17: Invoice | BQ17: 0 Days 3 Hr 35 Min | BR17: 800 | BS17: Approved - ;; Approved - ;; Approved - ok ; | BT17: 46327 | BU17: 46327 | BV17: ; | BW17: ; | BX17: ; | BY17: BR | CA17: USD | CF17: 1 | CG17: 1 | CJ17: 0 | CO17: 428456263
A18: 44927 | B18: Internal problem - Manufacturing/ Ordering/ Purchasing/ IT | C18: 41146 | D18: Ordering Erro Acumulado | E18: VW | F18: 44938 | G18: Pinhal | H18: Inbound Premium | I18: 512.17 | J18: 823 | K18: =I18/$I$1 -> 0.0012536323 | L18: PC-Plant PC Resp | M18: Normal | N18: APTIV MANUFATURA E SERVICOS DE-104991 | O18: APTIV SERVICES DEUTSCHLAND GMBH-103215 | P18: Air Freight required due to communication problems with the supplier, which caused errors in the accumulated. | Q18: DHL Express SA | R18: PTA-00086957 | S18: 15365811; | T18: ; | U18: ; | V18: Aptiv | W18: Premium - Productive | X18: bruno.g.silva2@aptiv.com | Y18: 44936.119 | Z18: 44958.087 | AA18: SA | AB18: Closed Not Recovered | AC18: 0 | AE18: 51217 | AF18: 44936 | AG18: 10010 | AH18: Q18 | AJ18: 51217 | AK18: Non-Recoverable | AM18: 823 | AN18: USD | AO18: BEUTHENER STRASSE 41 | AP18: NUREMBERG | AQ18: 103215 | AR18: DE | AS18: EMEA | AT18: BY | AU18: 90329 | AV18: RODOVIA SP 342 KM 196 | AW18: ESPIRITO SANTO DO PINHAL | AX18: 104991 | AY18: BR | AZ18: SA | BA18: SP | BB18: 13990-000 | BC18: SPS | BD18: Approved | BE18: Lopez, Tanya S | BF18: 44937.222 | BG18: 0 | BH18: DHL Express SA | BI18: 1534280355 | BK18: Aptiv | BM18: Personal Estimate | BN18: Invoice | BQ18: 1 Days 2 Hr 29 Min | BR18: 1000 | BS18: Approved - ;; Approved - ;; Approved - ok ;; Approved - ; | BT18: 51217 | BU18: 51217 | BV18: ; | BW18: ; | BX18: ; | BY18: BR | BZ18: 23X | CA18: USD | CF18: 1 | CG18: 1 | CJ18: 0
A19: 44927 | B19: Project | C19: 41163 | D19: Projeto | E19: FIAT | F19: 44936 | G19: Paraisopolis | H19: Inbound Premium | I19: 38 | J19: 38 | K19: =I19/$I$1 -> 9.3012138e-05 | L19: E1P-Prototypes/Samples | M19: Normal | N19: Paraisopolis-10012 | O19: SERENDIPITY ELECTRONICS-749804 | P19: Parts for sales from protoypes pieces. Freigth included in the piece price. | Q19: DHL Express SA | R19: PTA-00086683 | S19: PE55625513532153; | T19: ; | U19: ; | V19: Aptiv | W19: Premium - Productive | X19: rayzza.peres@aptiv.com | Y19: 44936.143 | Z19: 44936.143 | AA19: SA | AB19: Closed Not Recovered | AC19: 0 | AE19: 38 | AG19: 10012 | AH19: Q11 | AJ19: 38 | AK19: Recoverable | AM19: 38 | AN19: USD | AO19: 152 E MAIN ST | AP19: HUNTINGTON | AQ19: 749804 | AR19: US | AS19: NA | AT19: NY | AU19: 11743-2958 | AV19: Av. Avelino Ribeiro, 900 | AW19: Paraisopolis | AX19: 10012 | AY19: BR | AZ19: SA | BA19: Mina | BB19: 37660-000 | BC19: SPS | BD19: Approved | BE19: Edilson, Geraldo | BF19: 44936.237 | BG19: 0 | BK19: Aptiv | BM19: Invoice | BN19: Invoice | BQ19: 0 Days 2 Hr 14 Min | BR19: 500 | BS19: Approved - ;; Approved - ; | BT19: 38 | BU19: 38 | BV19: ; | BW19: ; | BX19: ; | BY19: BR | BZ19: GSE ORVR PL8 | CA19: USD | CE19: DPP67537 | CF19: 1 | CG19: 1 | CJ19: 0
A20: 44927 | B20: P&A | C20: 41253 | D20: P&A | E20: JOHN DEERE | F20: 44936 | G20: Paraisopolis | H20: Inbound Premium | I20: 691.42 | J20: 400 | K20: =I20/$I$1 -> 0.0016923803 | L20: OOOT-Other/Sales | M20: Normal | N20: APTIV MANUFATURA E SERVICOS DE-104120 | O20: LEONI CABLE-115491 | P20: DEMAND FOR P&A SERVICE | Q20: DHL Express SA | R20: PTA-00086889 | S20: M7600101; | T20: ; | U20: ; | V20: Aptiv | W20: Premium - Productive | X20: jorge.luis.almeida@aptiv.com | Y20: 44936.296 | Z20: 44961.514 | AA20: SA | AB20: Closed Not Recovered | AC20: 0 | AE20: 69142 | AG20: 10012 | AH20: Q11 | AJ20: 69142 | AK20: Non-Recoverable | AM20: 400 | AN20: USD | AO20: 321 EAST 2ND STREET SUITE B | AP20: ROCHESTER | AQ20: 115491 | AR20: US | AS20: NA | AT20: MI | AU20: 48307 | AV20: AVENIDA AVELINO RIBEIRO, 900 | AW20: PARAISOPOLIS | AX20: 104120 | AY20: BR | AZ20: SA | BA20: MG | BB20: 37660-000 | BC20: SPS | BD20: Approved | BE20: Edilson, Geraldo | BF20: 44937.459 | BG20: 0 | BH20: DHL Express SA | BI20: 4892732460 | BK20: Aptiv | BM20: Invoice | BN20: Invoice | BQ20: 0 Days 15 Hr 53 Min | BR20: 500 | BS20: Approved - ;; Approved - ; | BT20: 69142 | BU20: 69142 | BV20: ; | BW20: ; | BX20: ; | BY20: BR | CA20: USD | CE20: demand for attend P&A - JD client | CF20: 1 | CG20: 1 | CJ20: 0
A21: 44927 | B21: Internal problem - Manufacturing/ Ordering/ Purchasing/ IT | C21: 41461 | D21: Ordering Erro Acumulado | E21: VW | F21: 44939 | G21: Pinhal | H21: Inbound Premium | I21: 250 | J21: 250 | K21: =I21/$I$1 -> 0.00061192196 | L21: PC-Plant PC Resp | M21: Normal | N21: APTIV MANUFATURA E SERVICOS DE-104991 | O21: APTIV SERVICES DEUTSCHLAND GMBH-103215 | P21: Air Freight required due to communication problems with the supplier, which caused errors in the accumulated. | Q21: DHL Express SA | R21: PTA-00087241 | S21: 33405737; | T21: ; | U21: ; | V21: Aptiv | W21: Premium - Productive | X21: bruno.g.silva2@aptiv.com | Y21: 44937.407 | Z21: 44960.121 | AA21: SA | AB21: Closed Not Recovered | AC21: 0 | AE21: 0 | AF21: 44937 | AG21: 10010 | AH21: Q18 | AJ21: 17265 | AK21: Non-Recoverable | AM21: 250 | AN21: USD | AO21: BEUTHENER STRASSE 41 | AP21: NUREMBERG | AQ21: 103215 | AR21: DE | AS21: EMEA | AT21: BY | AU21: 90329 | AV21: RODOVIA SP 342 KM 196 | AW21: ESPIRITO SANTO DO PINHAL | AX21: 104991 | AY21: BR | AZ21: SA | BA21: SP | BB21: 13990-000 | BC21: SPS | BD21: Approved | BE21: Edilson, Geraldo | BF21: 44938.108 | BG21: 0 | BH21: DHL Express SA | BI21: 4724361110 | BK21: Aptiv | BM21: Personal Estimate | BN21: Invoice | BQ21: 1 Days 4 Hr 49 Min | BR21: 500 | BS21: Approved - ;; Approved - ; | BT21: 250 | BU21: 250 | BV21: ; | BW21: ; | BX21: ; | BY21: BR | BZ21: 23X | CA21: USD | CF21: 1 | CG21: 1 | CJ21: 0
A22: 44927 | B22: Shipment delay | C22: 41481 | D22: Transportation Problem - Atraso ETA | E22: GM | F22: 44938 | G22: Pinhal | H22: Inbound Premium | I22: 543.83 | J22: 150 | K22: =I22/$I$1 -> 0.0013311261 | L22: T1-Transportation | M22: Normal | N22: APTIV MANUFATURA E SERVICOS DE-104991 | O22: KOSTAL KONTAKT SYSTEME, INC-701557 | P22: Aéreo necessário devido ao atraso de ETA da Invoice 502075. | Q22: DHL Express SA | R22: PTA-00087247 | S22: 13869004; | T22: ; | U22: ; | V22: Aptiv | W22: Premium - Productive | X22: rodrigo.perez@aptiv.com | Y22: 44937.064 | Z22: 44957.516 | AA22: SA | AB22: Closed Not Recovered | AC22: 0 | AE22: 54383 | AF22: 44937 | AG22: 10010 | AH22: Q18 | AJ22: 54383 | AK22: Non-Recoverable | AM22: 150 | AN22: USD | AO22: 1350 W HAMLIN RD | AP22: ROCHESTER HILLS | AQ22: 701557 | AR22: US | AS22: NA | AT22: MI | AU22: 48309 | AV22: RODOVIA SP 342 KM 196 | AW22: ESPIRITO SANTO DO PINHAL | AX22: 104991 | AY22: BR | AZ22: SA | BA22: SP | BB22: 13990-000 | BC22: SPS | BD22: Approved | BE22: Edilson, Geraldo | BF22: 44938.13 | BG22: 0 | BH22: DHL Express SA | BI22: 1203350293 | BK22: Transportation | BM22: Personal Estimate | BN22: Personal Estimate | BQ22: 1 Days 1 Hr 35 Min | BR22: 500 | BS22: Approved - ;; Approved - ; | BT22: 54383 | BU22: 54383 | BV22: ; | BW22: ; | BX22: ; | BY22: BR | CA22: USD | CE22: 13735326 | CF22: 1 | CG22: 1 | CJ22: 0
A23: 44927 | B23: Stock discrepancy | C23: 41773 | D23: Stock Discrepancy | E23: GM | F23: 44938 | G23: Paraisopolis | H23: Inbound Premium | I23: 140.96 | J23: 140.96 | K23: =I23/$I$1 -> 0.00034502608 | L23: S1I-Inventory loss/adjustments | M23: Normal | N23: Paraisopolis-10012 | O23: A123 SYSTEMS (CHINA) MATERIALS CO-1041023 | P23: Tivemos uma Rolagen de 7 dias - consumo de 1000 peças sem estar planejado - divergencia de estoque de 1185 peças | Q23: DHL Express SA | R23: PTA-00087230 | S23: 25329659; | T23: ; | U23: ; | V23: Aptiv | W23: Premium - Productive | X23: william.de.siqueira@aptiv.com | Y23: 44938.509 | Z23: 44949.324 | AA23: SA | AB23: Closed Not Recovered | AC23: 0 | AE23: 14096 | AF23: 44945 | AG23: 10012 | AH23: Q11 | AJ23: 14096 | AK23: Non-Recoverable | AM23: 14096 | AN23: USD | AO23: A5 BUILDING, XINZHU RD. | AP23: CHANGZHOU | AQ23: 1041023 | AR23: CN | AS23: AP | AT23: 100 | AU23: 213031 | AV23: Av. Avelino Ribeiro, 900 | AW23: Paraisopolis | AX23: 10012 | AY23: BR | AZ23: SA | BA23: Mina | BB23: 37660-000 | BC23: SPS | BD23: Approved | BE23: Edilson, Geraldo | BF23: 44938.538 | BG23: 0 | BI23: 5827058440 | BK23: Aptiv | BM23: Invoice | BN23: Invoice | BQ23: 0 Days 0 Hr 41 Min | BR23: 500 | BS23: Approved - ;; Approved - ; | BT23: 14096 | BU23: 14096 | BV23: ; | BW23: ; | BX23: ; | BY23: BR | CA23: USD | CF23: 1 | CG23: 1 | CJ23: 0 | CO23: 544702061
A24: 44927 | B24: Stock discrepancy | C24: 41795 | D24: Stock Discrepancy | E24: GM | F24: 44939 | G24: Pinhal | H24: Inbound Premium | I24: 2191.89 | J24: 2000 | K24: =I24/$I$1 -> 0.0053650625 | L24: S1I-Inventory loss/adjustments | M24: Normal | N24: APTIV MANUFATURA E SERVICOS DE-104991 | O24: APTIV HONDURAS HN11-765569 | P24: We had some problems in the transportation of Aptiv Hondura's materials that results in iventory loss. | Q24: DSV UTI Air & Sea Agenciamento de Transportes | R24: PTA-00087693 | S24: 35578211; | T24: ; | U24: ; | V24: Aptiv | W24: Premium - Productive | X24: rodrigo.perez@aptiv.com | Y24: 44938.092 | Z24: 44957.519 | AA24: SA | AB24: Closed Not Recovered | AC24: 0 | AE24: 219189 | AF24: 44938 | AG24: 10010 | AH24: Q18 | AJ24: 219189 | AK24: Non-Recoverable | AM24: 2000 | AN24: USD | AO24: KM 23/24 CARRETERA A OCCIDENTE ZOLI | AP24: QUIMISTAN | AQ24: 765569 | AR24: HN | AS24: NA | AT24: SB | AU24: 22101 | AV24: RODOVIA SP 342 KM 196 | AW24: ESPIRITO SANTO DO PINHAL | AX24: 104991 | AY24: BR | AZ24: SA | BA24: SP | BB24: 13990-000 | BC24: SPS | BD24: Approved | BE24: Garcia Puente, Jorge | BF24: 44940.076 | BG24: 0 | BH24: DSV UTI Air & Sea Agenciamento de Transportes | BI24: SAP501006953 | BK24: Aptiv | BM24: Personal Estimate | BN24: Personal Estimate | BQ24: 1 Days 11 Hr 37 Min | BR24: 5000 | BS24: Approved - ;; Approved - ;; Approved - ;; Approved - ;; Approved - ; | BT24: 219189 | BU24: 219189 | BV24: ; | BW24: ; | BX24: ; | BY24: BR | CA24: USD | CF24: 1 | CG24: 1 | CJ24: 0
A25: 44927 | B25: Shipment delay | C25: 41799 | D25: Transportation Problem - Atraso ETA | E25: GM | F25: 44939 | G25: Pinhal | H25: Inbound Premium | I25: 464.65 | J25: 250 | K25: =I25/$I$1 -> 0.0011373182 | L25: T1-Transportation | M25: Normal | N25: APTIV MANUFATURA E SERVICOS DE-104991 | O25: APTIV SERVICES US LLC-111089 | P25: Aéreo necessário devido ao atraso de ETA do navio MONTE CERVANTES. Invoice Afetada : 11052167. | Q25: DHL Express SA | R25: PTA-00087245 | S25: 15482324; | T25: ; | U25: ; | V25: Aptiv | W25: Premium - Productive | X25: rodrigo.perez@aptiv.com | Y25: 44938.098 | Z25: 44957.52 | AA25: SA | AB25: Closed Not Recovered | AC25: 0 | AE25: 46465 | AF25: 44938 | AG25: 10010 | AH25: Q18 | AJ25: 46465 | AK25: Non-Recoverable | AM25: 250 | AN25: USD | AO25: 5725 DELPHI DR | AP25: TROY | AQ25: 111089 | AR25: US | AS25: NA | AT25: MI | AU25: 48098-2815 | AV25: RODOVIA SP 342 KM 196 | AW25: ESPIRITO SANTO DO PINHAL | AX25: 104991 | AY25: BR | AZ25: SA | BA25: SP | BB25: 13990-000 | BC25: SPS | BD25: Approved | BE25: Edilson, Geraldo | BF25: 44938.126 | BG25: 0 | BH25: DHL Express SA | BI25: 5403900563 | BK25: Transportation | BM25: Personal Estimate | BN25: Personal Estimate | BQ25: 0 Days 0 Hr 40 Min | BR25: 500 | BS25: Approved - ;; Approved - ; | BT25: 46465 | BU25: 46465 | BV25: ; | BW25: ; | BX25: ; | BY25: BR | CA25: USD | CF25: 1 | CG25: 1 | CJ25: 0
A26: 44927 | B26: Shipment delay | C26: 41899 | D26: Transportation Problem - Atraso ETA | E26: TOYOTA | F26: 44939 | G26: Paraisopolis | H26: Inbound Premium | I26: 310.16 | J26: 255 | K26: =I26/$I$1 -> 0.00075917486 | L26: PORT-PORT DELAYS | M26: Normal | N26: APTIV MANUFATURA E SERVICOS DE-104120 | O26: D.A. INC.-1048429 | P26: atraso de processo devido à torca de booking entre o navio monte azul para o monte olivia | Q26: DHL Express SA | R26: PTA-00087324 | S26: 13653037; | T26: ; | U26: 6000.00; | V26: Aptiv | W26: Premium - Productive | X26: jorge.luis.almeida@aptiv.com | Y26: 44938.288 | Z26: 44961.515 | AA26: SA | AB26: Closed Not Recovered | AC26: 0 | AE26: 31016 | AG26: 10012 | AH26: Q11 | AJ26: 31016 | AK26: Non-Recoverable | AM26: 255 | AN26: USD | AO26: 100 LINDBERGH DR | AP26: SANTA TERESA | AQ26: 1048429 | AR26: US | AS26: NA | AT26: NM | AU26: 88008-9706 | AV26: AVENIDA AVELINO RIBEIRO, 900 | AW26: PARAISOPOLIS | AX26: 104120 | AY26: BR | AZ26: SA | BA26: MG | BB26: 37660-000 | BC26: SPS | BD26: Approved | BE26: Edilson, Geraldo | BF26: 44938.302 | BG26: 0 | BH26: DHL Express SA | BI26: 7740203236 | BK26: Significant_event | BM26: Invoice | BN26: Invoice | BQ26: 0 Days 0 Hr 19 Min | BR26: 500 | BS26: Approved - ;; Approved - ; | BT26: 31016 | BU26: 31016 | BV26: ; | BW26: ; | BX26: ; | BY26: BR | CA26: USD | CE26: atraso de processo devido à torca de booking entre o navio monte azul para o monte olivia | CF26: 1 | CG26: 1 | CJ26: 0 | CO26: 690984533
A27: 44927 | B27: P&A | C27: 42182 | D27: P&A | E27: VW | F27: 44939 | G27: Paraisopolis | H27: Inbound Premium | I27: 28.48 | J27: 28.48 | K27: =I27/$I$1 -> 6.9710149e-05 | L27: OOOT-Other/Sales | M27: Normal | N27: APTIV MANUFATURA E SERVICOS DE-104120 | O27: SERENDIPITY ELECTRONICS-110404 | P27: Material to meet MAN customer's P&A program. | Q27: DHL Express SA | R27: PTA-00087890 | S27: 13741166; | T27: 100; | U27: 0.45; | V27: Aptiv | W27: Premium - Productive | X27: marcia.p.torres@aptiv.com | Y27: 44939.131 | Z27: 44960.242 | AA27: SA | AB27: Closed Not Recovered | AC27: 0 | AE27: 2848 | AF27: 44939 | AG27: 10012 | AH27: Q11 | AJ27: 2848 | AK27: Non-Recoverable | AM27: 2848 | AN27: USD | AO27: 152 E MAIN ST | AP27: HUNTINGTON | AQ27: 110404 | AR27: US | AS27: NA | AT27: NY | AU27: 11743-2958 | AV27: AVENIDA AVELINO RIBEIRO, 900 | AW27: PARAISOPOLIS | AX27: 104120 | AY27: BR | AZ27: SA | BA27: MG | BB27: 37660-000 | BC27: SPS | BD27: Approved | BE27: Edilson, Geraldo | BF27: 44942.46 | BG27: 0 | BH27: DHL Express SA | BI27: 2903559993 | BK27: Aptiv | BM27: Invoice | BN27: Invoice | BQ27: 2 Days 19 Hr 53 Min | BR27: 500 | BS27: Approved - ;; Approved - ; | BT27: 2848 | BU27: 2848 | BV27: 1; | BW27: 12x9x4; | BX27: ; | BY27: BR | BZ27: P&A | CA27: USD | CD27: Kg | CE27: Material to meet MAN customer's P&A program. | CF27: 1 | CG27: 1 | CJ27: 0
A28: 44927 | B28: Project | C28: 42654 | D28: Projeto | E28: JOHN DEERE | F28: 44943 | G28: Paraisopolis | H28: Inbound Premium | I28: 180 | J28: 180 | K28: =I28/$I$1 -> 0.00044058381 | L28: E1P-Prototypes/Samples | M28: Cost Recovery Pending | N28: Paraisopolis-10012 | O28: CHIEF ENTERPRISES INC-767169 | P28: Parts for project development. Freight will be absorbed at the SC 126-22 quotation. | Q28: DHL Express SA | R28: PTA-00087995 | S28: 35209963; | T28: ; | U28: ; | V28: Aptiv | W28: Premium - Productive | X28: william.de.siqueira@aptiv.com | Y28: 44942.241 | Z28: 44942.241 | AA28: SA | AB28: Open | AC28: 0 | AE28: 0 | AF28: 44949 | AG28: 10012 | AH28: Q11 | AK28: Recoverable | AM28: 180 | AO28: 545 WEST LAKE STREET | AP28: ELMHURST | AQ28: 767169 | AR28: US | AS28: NA | AT28: IL | AU28: 60126 | AV28: Av. Avelino Ribeiro, 900 | AW28: Paraisopolis | AX28: 10012 | AY28: BR | AZ28: SA | BA28: Mina | BB28: 37660-000 | BC28: SPS | BD28: Approved | BE28: Carvalho, Eliane R | BF28: 44942.254 | BG28: 0 | BK28: Aptiv | BM28: Invoice | BQ28: 0 Days 0 Hr 18 Min | BR28: 250 | BS28: Approved - ;; Approved - ; | BT28: 180 | BU28: 180 | BV28: ; | BW28: ; | BX28: ; | BY28: BR | CA28: USD | CF28: 1 | CJ28: 0
A29: 44927 | B29: Project | C29: 42655 | D29: Projeto | E29: JOHN DEERE | F29: 44943 | G29: Paraisopolis | H29: Inbound Premium | I29: 69.31 | J29: 60 | K29: =I29/$I$1 -> 0.00016964924 | L29: E1P-Prototypes/Samples | M29: Cost Recovery Pending | N29: Paraisopolis-10012 | O29: APPARATEBAU KIRCHHEIM-TECK GMBH-7043806 | P29: Parts for project development. Freight will be absorbed at the SC 126-22 quotation. | Q29: DHL Express SA | R29: PTA-00088233 | S29: 15339884; | T29: ; | U29: ; | V29: Aptiv | W29: Premium - Productive | X29: william.de.siqueira@aptiv.com | Y29: 44942.243 | Z29: 44953.118 | AA29: SA | AB29: Open | AC29: 0 | AE29: 6931 | AF29: 44949 | AG29: 10012 | AH29: Q11 | AJ29: 6931 | AK29: Recoverable | AM29: 60 | AN29: USD | AO29: ALLEENSTR. 36 | AP29: KIRCHHEIM UNTER TECK | AQ29: 7043806 | AR29: DE | AS29: EMEA | AT29: BW | AU29: 73230 | AV29: Av. Avelino Ribeiro, 900 | AW29: Paraisopolis | AX29: 10012 | AY29: BR | AZ29: SA | BA29: Mina | BB29: 37660-000 | BC29: SPS | BD29: Approved | BE29: Carvalho, Eliane R | BF29: 44943.538 | BG29: 0 | BI29: 6376562323 | BK29: Aptiv | BM29: Invoice | BN29: Invoice | BQ29: 0 Days 19 Hr 5 Min | BR29: 250 | BS29: Approved - ;; Approved - ; | BT29: 6931 | BU29: 6931 | BV29: ; | BW29: ; | BX29: ; | BY29: BR | CA29: USD | CF29: 1 | CG29: 1 | CJ29: 0 | CO29: 315566067
A30: 44927 | B30: Shipment delay | C30: 42712 | D30: Transportation Problem - Atraso ETA | E30: TOYOTA | F30: 44943 | G30: Paraisopolis | H30: Inbound Premium | I30: 224.79 | J30: 120 | K30: =I30/$I$1 -> 0.00055021575 | L30: T1-Transportation | M30: Normal | N30: APTIV MANUFATURA E SERVICOS DE-104120 | O30: APTIV LAREDO (FW80)-734188 | P30: INVOICE 10829477 SEM MANIFESTAR E NÃO TEMOS CERTEZA EM QUAL PROCESSO ESTÁ FISICAMENTE | Q30: DHL Express SA | R30: PTA-00088032 | S30: 13533399; | T30: ; | U30: ; | V30: Aptiv | W30: Premium - Productive | X30: Moraes.Arnaldo@aptiv.com | Y30: 44942.319 | Z30: 44960.191 | AA30: SA | AB30: Closed Not Recovered | AC30: 0 | AE30: 22479 | AG30: 10012 | AH30: Q11 | AJ30: 22479 | AK30: Non-Recoverable | AM30: 120 | AN30: USD | AO30: 301 VALLECILLO ROAD | AP30: LAREDO | AQ30: 734188 | AR30: US | AS30: NA | AT30: TX | AU30: 78045-7847 | AV30: AVENIDA AVELINO RIBEIRO, 900 | AW30: PARAISOPOLIS | AX30: 104120 | AY30: BR | AZ30: SA | BA30: MG | BB30: 37660-000 | BC30: SPS | BD30: Approved | BE30: Carvalho, Eliane R | BF30: 44942.338 | BG30: 0 | BI30: 3831132826 | BK30: Transportation | BM30: Personal Estimate | BN30: Invoice | BQ30: 0 Days 0 Hr 27 Min | BR30: 250 | BS30: Approved - ;; Approved - ; | BT30: 22479 | BU30: 22479 | BV30: ; | BW30: ; | BX30: ; | BY30: BR | CA30: USD | CF30: 1 | CG30: 1 | CJ30: 0
A31: 44927 | B31: Customer reschedule | C31: 42717 | D31: Customer Reschedule VW | E31: VW | F31: 44942 | G31: Pinhal | H31: Inbound Premium | I31: 401.52 | J31: 401.52 | K31: =I31/$I$1 -> 0.00098279562 | L31: C4-Capacity-External Customer Resp | M31: Cost Recovery Pending | N31: APTIV MANUFATURA E SERVICOS DE-104991 | O31: Arniflex Monte Alto-Dummy | P31: Customer Reschedule | Q31: TRANSPORTADORA PITUTA | R31: PTA-00088356 | S31: 13921536; | T31: ; | U31: ; | V31: Customer | W31: Premium - Productive | X31: adriane.barbosa.silva@aptiv.com | Y31: 44942.337 | Z31: 44946.222 | AA31: SA | AB31: Closed Not Recovered | AC31: 0 | AE31: 0 | AG31: 10010 | AH31: Q18 | AJ31: 211341 | AK31: Non-Recoverable | AM31: 2095 | AN31: BRL | AO31: Monte Alto | AP31: Monte Alto | AQ31: Dummy | AR31: BR | AS31: SA | AT31: Sao Paulo | AU31: 0000 | AV31: RODOVIA SP 342 KM 196 | AW31: ESPIRITO SANTO DO PINHAL | AX31: 104991 | AY31: BR | AZ31: SA | BA31: SP | BB31: 13990-000 | BC31: SPS | BD31: Approved | BE31: Edilson, Geraldo | BF31: 44943.262 | BG31: 0 | BH31: TRANSPORTADORA PITUTA | BI31: ESP-000037266 | BK31: Customer | BM31: Invoice | BN31: Invoice | BQ31: 0 Days 22 Hr 11 Min | BR31: 500 | BS31: Approved - ;; Approved - ;; Approved - ; | BT31: 40152 | BU31: 40152 | BV31: ; | BW31: ; | BX31: ; | BY31: BR | CA31: BRL | CF31: 19165533 | CG31: 19165533 | CJ31: 0
A32: 44927 | B32: Project | C32: 42868 | D32: BOM Error | E32: FIAT | F32: 44944 | G32: Paraisopolis | H32: Inbound Premium | I32: 432.88 | J32: 420 | K32: =I32/$I$1 -> 0.0010595551 | L32: E1B-BOM Errors | M32: Normal | N32: Paraisopolis-10012 | O32: MTA S P A-737725 | P32: Atraso na implementação da BP por parte da Engenharia - A SSCR deu início em 03/06/2022 e a logistica foi informada apenas 03/10/2022 sobre a obsolecencia. E O BP só foi efetivado na semana 48 onde reprogramamos a MTA de imediato. | Q32: DHL Express SA | R32: PTA-00088302 | S32: 10864719; | T32: ; | U32: ; | V32: Aptiv | W32: Premium - Productive | X32: william.de.siqueira@aptiv.com | Y32: 44943.539 | Z32: 44949.325 | AA32: SA | AB32: Closed Not Recovered | AC32: 0 | AE32: 43288 | AF32: 44950 | AG32: 10012 | AH32: Q11 | AJ32: 43288 | AK32: Non-Recoverable | AM32: 420 | AN32: USD | AO32: VIALE DELLINDUSTRIA 12 | AP32: CODOGNO | AQ32: 737725 | AR32: IT | AS32: EMEA | AT32: LO | AU32: 26845 | AV32: Av. Avelino Ribeiro, 900 | AW32: Paraisopolis | AX32: 10012 | AY32: BR | AZ32: SA | BA32: Mina | BB32: 37660-000 | BC32: SPS | BD32: Approved | BE32: Edilson, Geraldo | BF32: 44943.093 | BG32: 0 | BI32: 4534512791 | BK32: Aptiv | BM32: Invoice | BN32: Invoice | BQ32: 0 Days 1 Hr 16 Min | BR32: 500 | BS32: Approved - ;; Approved - ;; Approved - ; | BT32: 43288 | BU32: 43288 | BV32: ; | BW32: ; | BX32: ; | BY32: BR | CA32: USD | CF32: 1 | CG32: 1 | CJ32: 0
A33: 44927 | B33: Internal problem - Manufacturing/ Ordering/ Purchasing/ IT | C33: 42926 | D33: Ordering Problem - Problemas com forecast causando atraso embarque fornecedor Aptiv Honduras | E33: GM | F33: 44944 | G33: Pinhal | H33: Inbound Premium | I33: 1690 | J33: 3000 | K33: =I33/$I$1 -> 0.0041365924 | L33: B2-Behind Schedule-Aptiv | M33: Normal | N33: APTIV MANUFATURA E SERVICOS DE-104991 | O33: APTIV HONDURAS HN11-765569 | P33: We had some problems with our forecasts with Aptiv Honduras that caused shipment delay. | Q33: DSV UTI Air & Sea Agenciamento de Transportes | R33: PTA-00088499 | S33: 47315377; | T33: ; | U33: ; | V33: Aptiv | W33: Premium - Productive | X33: rodrigo.perez@aptiv.com | Y33: 44943.158 | Z33: 44957.521 | AA33: SA | AB33: Closed Not Recovered | AC33: 0 | AE33: 1690 | AF33: 44943 | AG33: 10010 | AH33: Q18 | AJ33: 1690 | AK33: Non-Recoverable | AM33: 3000 | AN33: USD | AO33: KM 23/24 CARRETERA A OCCIDENTE ZOLI | AP33: QUIMISTAN | AQ33: 765569 | AR33: HN | AS33: NA | AT33: SB | AU33: 22101 | AV33: RODOVIA SP 342 KM 196 | AW33: ESPIRITO SANTO DO PINHAL | AX33: 104991 | AY33: BR | AZ33: SA | BA33: SP | BB33: 13990-000 | BC33: SPS | BD33: Approved | BE33: Garcia Puente, Jorge | BF33: 44944.051 | BG33: 0 | BH33: DSV UTI Air & Sea Agenciamento de Transportes | BI33: SAP501006954 | BK33: Aptiv | BM33: Personal Estimate | BN33: Personal Estimate | BQ33: 0 Days 9 Hr 25 Min | BR33: 5000 | BS33: Approved - ;; Approved - ;; Approved - ;; Approved - ;; Approved - ;; Approved - ; | BT33: 1690 | BU33: 1690 | BV33: ; | BW33: ; | BX33: ; | BY33: BR | CA33: USD | CE33: 47315378 | CF33: 1 | CG33: 1 | CJ33: 0
A34: 44927 | B34: Shipment delay | C34: 43056 | D34: Transportation Problem - Atraso ETA | E34: GM | F34: 44944 | G34: Pinhal | H34: Inbound Premium | I34: 410.71 | J34: 410.71 | K34: =I34/$I$1 -> 0.0010052899 | L34: PC-Plant PC Resp | M34: Normal | N34: APTIV MANUFATURA E SERVICOS DE DIST-1039282 | O34: Empresa de Transportes Covre-Dummy | P34: Entrega Emergencial da Pasta M1018/22, para evitar parada de linha GM. | Q34: EMPRESA DE TRANSPORTES COVRE | R34: PTA-00088408 | S34: 47315375; | T34: ; | U34: ; | V34: Aptiv | W34: Premium - Productive | X34: rodrigo.perez@aptiv.com | Y34: 44943.307 | Z34: 44957.523 | AA34: SA | AB34: Closed Not Recovered | AC34: 0 | AE34: 41071 | AF34: 44943 | AG34: 10010 | AH34: Q18 | AJ34: 41071 | AK34: Non-Recoverable | AM34: 41071 | AN34: USD | AO34: R. Hercílio Camargo Barbosa, 207 | AP34: Santos | AQ34: Dummy | AR34: BR | AS34: SA | AT34: Sao Paulo | AU34: 11095-590 | AV34: RUA JOSE MONFARDINI 3845 | AW34: ESPIRITO SANTO DO PINHAL | AX34: 1039282 | AY34: BR | AZ34: SA | BA34: SP | BB34: 13990-000 | BC34: SPS | BD34: Approved | BE34: Edilson, Geraldo | BF34: 44943.343 | BG34: 0 | BH34: EMPRESA DE TRANSPORTES COVRE | BI34: ENTREGA EMERGENCIAL | BK34: Aptiv | BM34: Personal Estimate | BN34: Personal Estimate | BQ34: 0 Days 0 Hr 52 Min | BR34: 500 | BS34: Approved - ;; Approved - ;; Approved - ; | BT34: 41071 | BU34: 41071 | BV34: ; | BW34: ; | BX34: ; | BY34: BR | CA34: USD | CF34: 1 | CG34: 1 | CJ34: 0 | CP34: 217616996
A35: 44927 | B35: Project | C35: 43063 | D35: Projeto | E35: OTHER | F35: 44944 | G35: Paraisopolis | H35: Inbound Premium | I35: 43 | J35: 0 | K35: =I35/$I$1 -> 0.00010525058 | L35: E1P-Prototypes/Samples | M35: Cost Recovery | N35: Paraisopolis-10012 | O35: SERENDIPITY ELECTRONICS, INC.-1062318 | P35: Parts for project development. Freight will be absorbed at the SC 564-21A quotation. | Q35: DHL Express SA | R35: PTA-00088622 | S35: 13949148PE55625513532153; | T35: ; | U35: ; | V35: Aptiv | W35: Premium - Productive | X35: rayzza.peres@aptiv.com | Y35: 44943.335 | Z35: 44944.145 | AA35: SA | AB35: Closed Recovered | AC35: 0 | AE35: 43 | AG35: 10012 | AH35: Q11 | AJ35: 43 | AK35: Recoverable | AM35: 43 | AN35: USD | AO35: 152 E MAIN ST STE D | AP35: HUNTINGTON | AQ35: 1062318 | AR35: US | AS35: NA | AT35: NY | AU35: 11743-2958 | AV35: Av. Avelino Ribeiro, 900 | AW35: Paraisopolis | AX35: 10012 | AY35: BR | AZ35: SA | BA35: Mina | BB35: 37660-000 | BC35: SPS | BD35: Approved | BE35: Carvalho, Eliane R | BF35: 44944.104 | BG35: 0 | BH35: DHL Express SA | BI35: 4405736580 | BK35: Aptiv | BM35: Invoice | BN35: Invoice | BQ35: 0 Days 18 Hr 27 Min | BR35: 250 | BS35: Approved - ;; Approved - ; | BT35: 43 | BU35: 43 | BV35: ; | BW35: ; | BX35: ; | BY35: BR | BZ35: CNH - ARO 10 | CA35: USD | CE35: DPP67537 DPP67622 | CF35: 1 | CG35: 1 | CJ35: 0 | CO35: 800114696
A36: 44927 | B36: Shipment delay | C36: 43397 | D36: Transportation Problem - Atraso ETA | E36: GM | F36: 44945 | G36: Pinhal | H36: Inbound Premium | I36: 740.44 | J36: 750 | K36: =I36/$I$1 -> 0.001812366 | L36: T1-Transportation | M36: Normal | N36: APTIV MANUFATURA E SERVICOS DE-104991 | O36: J.S.T. CORPORATION-7025683 | P36: Air Freight needed due to the ETA delay of ONE HAWK. | Q36: DHL Express SA | R36: PTA-00088853 | S36: 13646861; | T36: ; | U36: ; | V36: Aptiv | W36: Premium - Productive | X36: rodrigo.perez@aptiv.com | Y36: 44944.297 | Z36: 44957.524 | AA36: SA | AB36: Closed Not Recovered | AC36: 0 | AE36: 74044 | AF36: 44944 | AG36: 10010 | AH36: Q18 | AJ36: 74044 | AK36: Non-Recoverable | AM36: 750 | AN36: USD | AO36: 37879 INTERCHANGE DR | AP36: FARMINGTON HILLS | AQ36: 7025683 | AR36: US | AS36: NA | AT36: MI | AU36: 48335-1024 | AV36: RODOVIA SP 342 KM 196 | AW36: ESPIRITO SANTO DO PINHAL | AX36: 104991 | AY36: BR | AZ36: SA | BA36: SP | BB36: 13990-000 | BC36: SPS | BD36: Approved | BE36: Naus, Angelica | BF36: 44945.074 | BG36: 0 | BH36: DHL Express SA | BI36: 5570183883 | BK36: Transportation | BM36: Invoice | BN36: Personal Estimate | BQ36: 0 Days 18 Hr 38 Min | BR36: 800 | BS36: Approved - ;; Approved - ;; Approved - ;; Approved - ; | BT36: 74044 | BU36: 74044 | BV36: ; | BW36: ; | BX36: ; | BY36: BR | CA36: USD | CE36: 13588505/13595476/35028910/35120496. | CF36: 1 | CG36: 1 | CJ36: 0 | CO36: 690666524
A37: 44927 | B37: Internal problem - Manufacturing/ Ordering/ Purchasing/ IT | C37: 43630 | D37: Ordering Problem - Problemas com forecast causando atraso embarque fornecedor Aptiv Honduras | E37: GM | F37: 44946 | G37: Pinhal | H37: Inbound Premium | I37: 2000 | J37: 2000 | K37: =I37/$I$1 -> 0.0048953757 | L37: B2-Behind Schedule-Aptiv | M37: Normal | N37: APTIV MANUFATURA E SERVICOS DE-104991 | O37: APTIV HONDURAS HN11-765569 | P37: We had some problems with our forecasts with Aptiv Honduras that caused shipment delay. | Q37: DSV UTI Air & Sea Agenciamento de Transportes | S37: 13818129; | T37: ; | U37: ; | V37: Aptiv | W37: Premium - Productive | X37: rodrigo.perez@aptiv.com | Y37: 44957.11 | Z37: 44957.11 | AA37: SA | AB37: Closed Not Recovered | AC37: 0 | AE37: 0 | AF37: 44945 | AG37: 10010 | AH37: Q18 | AK37: Non-Recoverable | AM37: 2000 | AO37: KM 23/24 CARRETERA A OCCIDENTE ZOLI | AP37: QUIMISTAN | AQ37: 765569 | AR37: HN | AS37: NA | AT37: SB | AU37: 22101 | AV37: RODOVIA SP 342 KM 196 | AW37: ESPIRITO SANTO DO PINHAL | AX37: 104991 | AY37: BR | AZ37: SA | BA37: SP | BB37: 13990-000 | BC37: SPS | BD37: Pending | BG37: 0 | BH37: DSV UTI Air & Sea Agenciamento de Transportes | BK37: Aptiv | BM37: Personal Estimate | BN37: Personal Estimate | BR37: 0 | BS37: Approved - ;; Approved - ;; Approved - ;; Approved - ok ;; Pending - | BT37: 2000 | BU37: 2000 | BV37: ; | BW37: ; | BX37: ; | BY37: BR | CA37: USD | CE37: 47315375/47314246/47315376 | CF37: 1 | CJ37: 0
A38: 44927 | B38: Stock discrepancy | C38: 43813 | D38: Stock Discrepancy | E38: JOHN DEERE | F38: 44949 | G38: Paraisopolis | H38: Inbound Premium | I38: 816.66 | J38: 248 | K38: =I38/$I$1 -> 0.0019989287 | L38: S1I-Inventory loss/adjustments | M38: Normal | N38: APTIV MANUFATURA E SERVICOS DE-104120 | O38: HARNESS CODE LTD OOD-7089652 | P38: Material inventariado erroneamente - risco de parada do cliente JD | Q38: Expeditors International | R38: PTA-00089104 | S38: 10737325; | T38: ; | U38: ; | V38: Aptiv | W38: Premium - Productive | X38: jorge.luis.almeida@aptiv.com | Y38: 44946.485 | Z38: 44961.515 | AA38: SA | AB38: Closed Not Recovered | AC38: 0 | AE38: 81666 | AG38: 10012 | AH38: Q11 | AJ38: 81666 | AK38: Non-Recoverable | AM38: 248 | AN38: USD | AO38: 12 DOSPAT STR./BLVD. | AP38: SOFIA | AQ38: 7089652 | AR38: BG | AS38: EMEA | AT38: 22 | AU38: 1606 | AV38: AVENIDA AVELINO RIBEIRO, 900 | AW38: PARAISOPOLIS | AX38: 104120 | AY38: BR | AZ38: SA | BA38: MG | BB38: 37660-000 | BC38: SPS | BD38: Approved | BE38: Carvalho, Eliane R | BF38: 44946.512 | BG38: 0 | BH38: Expeditors International | BI38: 2977928590 | BK38: Aptiv | BM38: Invoice | BN38: Invoice | BQ38: 0 Days 0 Hr 38 Min | BR38: 250 | BS38: Approved - ;; Approved - ; | BT38: 81666 | BU38: 81666 | BV38: ; | BW38: ; | BX38: ; | BY38: BR | BZ38: 6M | CA38: USD | CE38: Mterial de baixo volume inventariado errado no inventário sem opção de desvio e com risco de parada do cliente JD | CF38: 1 | CG38: 1 | CJ38: 0 | CO38: 507488352
A39: 44927 | B39: Shipment delay | C39: 43815 | D39: Transportation Problem - Atraso ETA | E39: GM | F39: 44946 | G39: Pinhal | H39: Inbound Premium | I39: 546.61 | J39: 442 | K39: =I39/$I$1 -> 0.0013379306 | L39: T1-Transportation | M39: Normal | N39: APTIV MANUFATURA E SERVICOS DE-104991 | O39: APTIV SERVICES US, LLC-1056313 | P39: Aéreo necessário devido ao atraso de ETA do Navio ONE HAWK. Invoices Afetadas : 10954307 / 11040992. | Q39: DHL Express SA | R39: PTA-00089116 | S39: 15429045; | T39: ; | U39: ; | V39: Aptiv | W39: Premium - Productive | X39: rodrigo.perez@aptiv.com | Y39: 44946.506 | Z39: 44957.53 | AA39: SA | AB39: Closed Not Recovered | AC39: 0 | AE39: 54661 | AF39: 44946 | AG39: 10010 | AH39: Q18 | AJ39: 54661 | AK39: Non-Recoverable | AM39: 442 | AN39: USD | AO39: AV. DE LAS INDUSTRIAS 1410 | AP39: CIUDAD JUAREZ | AQ39: 1056313 | AR39: MX | AS39: NA | AT39: CHH | AU39: 32470 | AV39: RODOVIA SP 342 KM 196 | AW39: ESPIRITO SANTO DO PINHAL | AX39: 104991 | AY39: BR | AZ39: SA | BA39: SP | BB39: 13990-000 | BC39: SPS | BD39: Approved | BE39: Edilson, Geraldo | BF39: 44946.089 | BG39: 0 | BH39: DHL Express SA | BI39: 1088515411 | BK39: Transportation | BM39: Personal Estimate | BN39: Personal Estimate | BQ39: 0 Days 1 Hr 59 Min | BR39: 500 | BS39: Approved - ;; Approved - ;; Approved - ; | BT39: 54661 | BU39: 54661 | BV39: ; | BW39: ; | BX39: ; | BY39: BR | CA39: USD | CE39: 15513474/15514821/35031567/35072403 | CF39: 1 | CG39: 1 | CJ39: 0 | CO39: 43898092
A40: 44927 | B40: Shipment delay | C40: 43816 | D40: Transportation Problem - Atraso ETA | E40: GM | F40: 44946 | G40: Pinhal | H40: Inbound Premium | I40: 581.54 | J40: 513 | K40: =I40/$I$1 -> 0.0014234284 | L40: T1-Transportation | M40: Normal | N40: APTIV MANUFATURA E SERVICOS DE-104991 | O40: APTIV SERVICES US, LLC-1001280 | P40: Aéreo necessário devido ao atraso de ETA do Navio ONE HAWK. Invoices Afetadas : 11052167 / 11134170. | Q40: DHL Express SA | R40: PTA-00089197 | S40: 15482324; | T40: ; | U40: ; | V40: Aptiv | W40: Premium - Productive | X40: rodrigo.perez@aptiv.com | Y40: 44946.511 | Z40: 44957.532 | AA40: SA | AB40: Closed Not Recovered | AC40: 0 | AE40: 58154 | AF40: 44946 | AG40: 10010 | AH40: Q18 | AJ40: 58154 | AK40: Non-Recoverable | AM40: 513 | AN40: USD | AO40: 1265 N RIVER RD NE | AP40: WARREN | AQ40: 1001280 | AR40: US | AS40: NA | AT40: OH | AU40: 44483-2352 | AV40: RODOVIA SP 342 KM 196 | AW40: ESPIRITO SANTO DO PINHAL | AX40: 104991 | AY40: BR | AZ40: SA | BA40: SP | BB40: 13990-000 | BC40: SPS | BD40: Approved | BE40: Naus, Angelica | BF40: 44946.288 | BG40: 0 | BH40: DHL Express SA | BI40: 1088803096 | BK40: Transportation | BM40: Personal Estimate | BN40: Personal Estimate | BQ40: 0 Days 6 Hr 39 Min | BR40: 800 | BS40: Approved - ;; Approved - ;; Approved - ;; Approved - ; | BT40: 58154 | BU40: 58154 | BV40: ; | BW40: ; | BX40: ; | BY40: BR | CA40: USD | CF40: 1 | CG40: 1 | CJ40: 0 | CO40: 217616996
...

Sheet Dashboard 2024
A1: DASHBOARD - MAIN REASONS - 2024 (jan - sep)
A2: Reason | B2: Total $ | C2: % | D2: CR | G2: no | K2: Target year 24 | N2: DASHBOARD - MAIN REASONS - 2023
A3: Carrier issue | B3: 18421.75 | C3: 0.025779404 | H3: Faturamento 2024 | K3: 236.48141 | N3: Reason | O3: MOTIVO | P3: Total $ | Q3: % | S3: =(GETPIVOTDATA("Total $",$N$3,"ORIG_PREMIUM_REASON_CODE","Cost Recovery")+GETPIVOTDATA("Total $",$N$3,"ORIG_PREMIUM_REASON_CODE","Cost Recovery Pending"))/1000000 -> 0.19046043
A4: Customer recheduled | B4: 195264.37 | C4: 0.27325303 | N4: Cost Recovery | O4: Freight to be recovery at POV | P4: 45701.32 | Q4: 0.17481593 | S4: =S3/I3 -> #DIV/0!
A5: Internal problem - Manufacturing/ Ordering/ Purchasing/ IT | B5: 15569.96 | C5: 0.021788608 | H5: Premium Total | I5: =GETPIVOTDATA("Total $",#REF!)/1000000 -> #REF! | K5: =K3*K6 -> 0.14188885 | O5: Freight recovered with the client | P5: 33678.99 | Q5: 0.12882832
A6: Internal strategy | B6: 59813.98 | C6: 0.083703707 | H6: % Premium Total/ fat | I6: =I5/I3 -> #REF! | K6: 0.0006 | O6: Customer reschedule | P6: 30968.96 | Q6: 0.11846195
A7: Lead time discrepancy between supplier/ customer | B7: 21493.11 | C7: 0.030077466 | O7: Project | P7: 25095.57 | Q7: 0.095995159
A8: P&A | B8: 11790.79 | C8: 0.016500036 | H8: CR Non recoverable | I8: =SUMIF(#REF!,$G$2,#REF!)/1000000 -> #REF! | O8: Freight recovered by POV | P8: 12690.38 | Q8: 0.048543032
A9: Stock discrepancy | B9: 18345.13 | C9: 0.025672182 | H9: % CR Non recoverable/ fat | I9: =I8/I3 -> #REF! | O9: Freight recovery by ICC | P9: 7980.1 | Q9: 0.030525346
A10: Vessel delay | B10: 75429.401 | C10: 0.10555593 | O10: Cargo lost | P10: 2723.27 | Q10: 0.010417007
A11: Port Strike + Vessel delay | B11: 161987.49 | C11: 0.22668536 | O11: Internal problem - Manufacturing/ Ordering/ Purchasing/ IT | P11: 1786.12 | Q11: 0.0068322367
A12: APTIV Shipment delay | B12: 19734.33 | C12: 0.027616229 | O12: Lead time discrepancy between supplier/ customer | P12: 1622.1 | Q12: 0.0062048301
A13: Total Geral | B13: 597850.31 | C13: 0.83663196 | O13: Stock discrepancy | P13: 1435.53 | Q13: 0.0054911656
O14: Supplier delay | P14: 1035.37 | Q14: 0.0039604802
O15: Freight to be recovered with supplier | P15: 411.18 | Q15: 0.0015728389
O16: P&A | P16: 169.03 | Q16: 0.00064657076
N17: Cost Recovery Total | P17: 165297.92 | Q17: 0.63229487
N19: Cost Recovery Pending | O19: Carrier issue | P19: 6078.36 | Q19: 0.023250842
O20: Freight to be recovered with client | P20: 4647.41 | Q20: 0.017777196
O21: Freight to be recovery at POV | P21: 4381.83 | Q21: 0.016761304
O22: Lead time discrepancy between supplier/ customer | P22: 3707 | Q22: 0.014179955
O23: Freight recovered by POV | P23: 2139.82 | Q23: 0.0081852041
O24: Customer reschedule | P24: 1209.17 | Q24: 0.0046252971
O25: Freight to be recovered with supplier | P25: 849.34 | Q25: 0.0032488813
O26: Shipment delay | P26: 689 | Q26: 0.0026355514
O27: Project | P27: 631.58 | Q27: 0.0024159094
O28: Internal strategy/ discount | P28: 479 | Q28: 0.0018322629
O29: Internal problem - Manufacturing/ Ordering/ Purchasing/ IT | P29: 350 | Q29: 0.0013388142
N30: Cost Recovery Pending Total | P30: 25162.51 | Q30: 0.096251217
N32: Normal | O32: Internal strategy/ discount | P32: 26502.38 | Q32: 0.10137647
O33: Lead time discrepancy between supplier/ customer | P33: 9978.85 | Q33: 0.038170932
